2021-09-05 22:15:39,722 [FTX GW      ] [INFO ]  Received: {"channel": "orderbook", "market": "BTC-PERP", "type": "partial", "data": {"time": 1630851340.6570554, "checksum": 3975705594, "bids": [[50492.0, 0.8454], [50491.0, 0.9953], [50490.0, 2.8681], [50489.0, 0.2663], [50488.0, 14.2327], [50487.0, 0.1397], [50483.0, 0.1917], [50482.0, 0.04], [50480.0, 0.6244], [50479.0, 2.5], [50476.0, 3.3234], [50475.0, 3.005], [50474.0, 2.1355], [50473.0, 10.5411], [50472.0, 3.7922], [50471.0, 0.7619], [50470.0, 6.2039], [50469.0, 5.4289], [50468.0, 3.068], [50467.0, 4.8818], [50466.0, 0.9903], [50465.0, 1.6893], [50464.0, 0.8642], [50463.0, 11.9904], [50461.0, 0.6889], [50460.0, 0.8366], [50459.0, 4.9592], [50458.0, 5.0914], [50456.0, 0.7646], [50455.0, 4.7132], [50454.0, 0.1642], [50452.0, 0.1692], [50451.0, 0.01], [50450.0, 1.395], [50449.0, 0.712], [50448.0, 2.2755], [50447.0, 7.0592], [50446.0, 0.4608], [50445.0, 0.01], [50441.0, 0.081], [50440.0, 2.4925], [50439.0, 0.01], [50438.0, 1.3737], [50437.0, 3.1832], [50436.0, 0.1901], [50435.0, 0.1544], [50434.0, 16.6701], [50433.0, 4.329], [50432.0, 0.007], [50431.0, 0.427], [50430.0, 0.1916], [50429.0, 5.4328], [50428.0, 1.3141], [50427.0, 0.1935], [50426.0, 2.7381], [50425.0, 1.088], [50424.0, 0.132], [50420.0, 1.6505], [50419.0, 0.2067], [50418.0, 0.443], [50417.0, 0.0456], [50416.0, 0.3925], [50413.0, 0.0112], [50412.0, 0.219], [50411.0, 0.8467], [50410.0, 0.0594], [50409.0, 2.9312], [50408.0, 0.06], [50407.0, 0.5035], [50406.0, 8.1521], [50405.0, 2.5809], [50404.0, 1.0], [50403.0, 0.0771], [50402.0, 0.05], [50401.0, 2.0019], [50400.0, 1.0023], [50399.0, 0.0616], [50398.0, 8.317], [50397.0, 0.3729], [50396.0, 1.4805], [50395.0, 3.8471], [50394.0, 1.4953], [50393.0, 0.0198], [50392.0, 0.2947], [50391.0, 0.0992], [50390.0, 2.148], [50389.0, 2.9902], [50388.0, 0.0698], [50387.0, 2.9078], [50386.0, 9.6613], [50385.0, 6.777], [50384.0, 0.0635], [50383.0, 18.9997], [50382.0, 0.6193], [50381.0, 2.498], [50380.0, 51.9276], [50379.0, 0.016], [50378.0, 0.6025], [50376.0, 0.2423], [50375.0, 0.0298]], "asks": [[50493.0, 0.3965], [50494.0, 0.1226], [50495.0, 1.1669], [50496.0, 0.2914], [50497.0, 0.04], [50498.0, 0.05], [50499.0, 0.2077], [50500.0, 78.8888], [50501.0, 0.01], [50502.0, 0.001], [50503.0, 0.4551], [50504.0, 0.0002], [50505.0, 0.338], [50506.0, 9.613], [50507.0, 3.6605], [50508.0, 3.9933], [50509.0, 1.1588], [50510.0, 1.6636], [50511.0, 1.5979], [50512.0, 14.8138], [50513.0, 0.5578], [50514.0, 3.1109], [50515.0, 0.9722], [50516.0, 0.064], [50517.0, 0.989], [50518.0, 0.1], [50519.0, 0.1763], [50520.0, 1.3286], [50521.0, 0.028], [50522.0, 0.4493], [50523.0, 2.5214], [50524.0, 3.1898], [50525.0, 3.1379], [50526.0, 1.3874], [50527.0, 3.7808], [50528.0, 2.352], [50529.0, 0.1112], [50530.0, 0.0525], [50531.0, 0.1974], [50532.0, 1.4127], [50533.0, 3.5336], [50534.0, 0.2862], [50535.0, 0.0111], [50536.0, 27.9072], [50537.0, 1.4121], [50538.0, 5.2996], [50539.0, 0.8193], [50540.0, 0.0199], [50541.0, 3.4636], [50542.0, 4.7419], [50543.0, 0.0638], [50544.0, 1.0375], [50545.0, 0.0811], [50546.0, 1.2032], [50547.0, 9.7002], [50548.0, 0.9505], [50549.0, 3.3195], [50550.0, 27.7852], [50551.0, 0.3346], [50552.0, 0.0105], [50553.0, 0.0673], [50554.0, 11.0872], [50555.0, 1.015], [50556.0, 0.0385], [50557.0, 0.0457], [50558.0, 2.2542], [50559.0, 0.2807], [50560.0, 0.0134], [50561.0, 0.0765], [50562.0, 0.1452], [50563.0, 7.3371], [50564.0, 0.0079], [50565.0, 0.0337], [50566.0, 0.0023], [50567.0, 0.2006], [50569.0, 0.0001], [50570.0, 4.9903], [50571.0, 0.7769], [50572.0, 3.2975], [50574.0, 0.0337], [50575.0, 0.079], [50576.0, 0.01], [50577.0, 7.8627], [50579.0, 15.7567], [50580.0, 3.4208], [50581.0, 10.0101], [50582.0, 0.0649], [50583.0, 50.7268], [50584.0, 11.6489], [50585.0, 0.0797], [50586.0, 0.7], [50588.0, 0.9131], [50589.0, 0.7748], [50590.0, 1.0261], [50591.0, 0.0616], [50592.0, 11.3727], [50593.0, 0.031], [50595.0, 0.0047], [50597.0, 1.8838], [50598.0, 18.0634]], "action": "partial"}}
2021-09-05 22:15:39,758 [FTX GW      ] [INFO ]  Received: {"channel": "orderbook", "market": "BTC-PERP", "type": "update", "data": {"time": 1630851340.7094188, "checksum": 645000214, "bids": [[50492.0, 3.3554], [50491.0, 1.2548], [50489.0, 0.0259], [50486.0, 0.0991], [50483.0, 0.5879], [50479.0, 0.0], [50477.0, 0.25], [50470.0, 7.1769], [50468.0, 3.0268], [50465.0, 1.6993], [50463.0, 12.5014], [50426.0, 28.0923], [50396.0, 0.1901], [50375.0, 0.0]], "asks": [[50494.0, 0.0956], [50509.0, 1.1648], [50510.0, 1.6736], [50516.0, 0.1571], [50522.0, 1.5493], [50523.0, 2.7029], [50540.0, 0.0299], [50593.0, 0.061]], "action": "update"}}
2021-09-05 22:15:39,791 [FTX GW      ] [INFO ]  Received: {"channel": "orderbook", "market": "BTC-PERP", "type": "update", "data": {"time": 1630851340.7315001, "checksum": 516283239, "bids": [[50492.0, 3.5954], [50490.0, 2.5081], [50463.0, 17.8786]], "asks": [[50520.0, 1.3386], [50530.0, 0.0939], [50538.0, 4.5403]], "action": "update"}}
2021-09-05 22:15:39,798 [FTX GW      ] [INFO ]  Received: {"channel": "orderbook", "market": "BTC-PERP", "type": "update", "data": {"time": 1630851340.7556663, "checksum": 1091471370, "bids": [[50492.0, 3.0554], [50491.0, 0.8817], [50490.0, 2.2681], [50470.0, 7.1869]], "asks": [[50493.0, 0.6865], [50535.0, 0.0299], [50551.0, 0.1109], [50558.0, 0.5831]], "action": "update"}}
2021-09-05 22:15:39,836 [FTX GW      ] [INFO ]  Received: {"channel": "orderbook", "market": "BTC-PERP", "type": "update", "data": {"time": 1630851340.7822597, "checksum": 3272805974, "bids": [[50480.0, 0.03], [50475.0, 2.7979], [50463.0, 17.2007]], "asks": [[50493.0, 1.9765]], "action": "update"}}
2021-09-05 22:15:39,854 [FTX GW      ] [INFO ]  Received: {"channel": "orderbook", "market": "BTC-PERP", "type": "update", "data": {"time": 1630851340.8089752, "checksum": 2752359273, "bids": [[50492.0, 2.8648], [50491.0, 0.2584], [50462.0, 1.0], [50461.0, 5.9828], [50376.0, 0.0]], "asks": [[50493.0, 3.9057], [50494.0, 0.4967], [50499.0, 0.2347], [50525.0, 3.1579], [50580.0, 3.9013]], "action": "update"}}
2021-09-05 22:15:39,877 [FTX GW      ] [INFO ]  Received: {"channel": "orderbook", "market": "BTC-PERP", "type": "update", "data": {"time": 1630851340.8321497, "checksum": 2469081173, "bids": [[50492.0, 2.1098], [50491.0, 0.0184], [50489.0, 0.0062], [50487.0, 0.0406], [50483.0, 0.1917], [50482.0, 0.54], [50477.0, 0.8444], [50470.0, 7.1769], [50466.0, 1.0316], [50380.0, 51.9296]], "asks": [[50493.0, 4.3757], [50511.0, 1.4988], [50517.0, 1.1], [50540.0, 0.0199]], "action": "update"}}
2021-09-05 22:15:39,905 [FTX GW      ] [INFO ]  Received: {"channel": "orderbook", "market": "BTC-PERP", "type": "update", "data": {"time": 1630851340.8587577, "checksum": 1403121195, "bids": [[50492.0, 1.2689], [50470.0, 7.1669], [50463.0, 11.8235]], "asks": [[50493.0, 5.1105], [50518.0, 0.1931], [50539.0, 1.3763], [50549.0, 4.0788], [50562.0, 0.3689]], "action": "update"}}
2021-09-05 22:15:39,936 [FTX GW      ] [INFO ]  Received: {"channel": "orderbook", "market": "BTC-PERP", "type": "update", "data": {"time": 1630851340.8795226, "checksum": 1886056645, "bids": [[50492.0, 0.9389], [50490.0, 0.8923], [50488.0, 13.5631], [50480.0, 0.0], [50466.0, 0.9903], [50376.0, 0.1911]], "asks": [[50493.0, 5.3113], [50520.0, 1.3286], [50534.0, 0.2345]], "action": "update"}}
2021-09-05 22:15:39,981 [FTX GW      ] [INFO ]  Received: {"channel": "orderbook", "market": "BTC-PERP", "type": "update", "data": {"time": 1630851340.919417, "checksum": 3762220465, "bids": [[50492.0, 1.7818], [50491.0, 0.9172], [50486.0, 0.0], [50477.0, 0.25], [50476.0, 3.8905], [50472.0, 3.1978], [50462.0, 0.3875], [50431.0, 0.001], [50375.0, 0.0298]], "asks": [[50493.0, 6.1785], [50510.0, 1.5745], [50523.0, 2.5214], [50536.0, 27.7248], [50549.0, 4.06]], "action": "update"}}
2021-09-05 22:15:40,057 [FTX GW      ] [INFO ]  Received: {"channel": "orderbook", "market": "BTC-PERP", "type": "update", "data": {"time": 1630851341.0092032, "checksum": 3271649987, "bids": [[50492.0, 0.0829], [50489.0, 0.0362], [50488.0, 13.5144], [50487.0, 0.0], [50482.0, 0.5], [50481.0, 0.1982], [50479.0, 0.3962], [50478.0, 0.5944], [50477.0, 0.0], [50468.0, 3.6212], [50465.0, 1.7606], [50462.0, 0.0], [50461.0, 0.6889], [50458.0, 13.8927], [50450.0, 1.7904], [50437.0, 3.6091], [50428.0, 1.7279]], "asks": [[50493.0, 7.5138], [50505.0, 0.4371], [50515.0, 0.9822], [50516.0, 0.7378], [50521.0, 0.0769], [50523.0, 2.5399], [50526.0, 1.9681], [50533.0, 3.7566], [50535.0, 0.0399]], "action": "update"}}
2021-09-05 22:15:40,109 [FTX GW      ] [INFO ]  Received: {"channel": "orderbook", "market": "BTC-PERP", "type": "update", "data": {"time": 1630851341.0588248, "checksum": 4158955757, "bids": [[50492.0, 0.0], [50452.0, 0.5723], [50374.0, 2.2784]], "asks": [[50492.0, 2.267], [50493.0, 7.4346], [50505.0, 0.5362], [50508.0, 1.2413], [50514.0, 3.204], [50598.0, 0.0]], "action": "update"}}
2021-09-05 22:15:40,134 [FTX GW      ] [INFO ]  Received: {"channel": "orderbook", "market": "BTC-PERP", "type": "update", "data": {"time": 1630851341.0931575, "checksum": 3179107579, "bids": [[50491.0, 0.8864], [50482.0, 2.5], [50466.0, 0.0], [50465.0, 1.7193], [50371.0, 2.6739]], "asks": [[50492.0, 2.627], [50499.0, 0.2077], [50533.0, 3.708], [50535.0, 0.0211]], "action": "update"}}
2021-09-05 22:15:40,176 [FTX GW      ] [INFO ]  Received: {"channel": "orderbook", "market": "BTC-PERP", "type": "update", "data": {"time": 1630851341.1332417, "checksum": 957437661, "bids": [[50489.0, 0.0062], [50473.0, 10.5914], [50463.0, 11.9903]], "asks": [[50492.0, 2.7379], [50493.0, 0.7951], [50499.0, 0.1877]], "action": "update"}}
2021-09-05 22:15:40,208 [FTX GW      ] [INFO ]  Received: {"channel": "orderbook", "market": "BTC-PERP", "type": "update", "data": {"time": 1630851341.1523318, "checksum": 2160900471, "bids": [[50457.0, 1.504], [50385.0, 6.888], [50371.0, 0.0]], "asks": [[50492.0, 14.9379], [50493.0, 0.394], [50514.0, 3.427]], "action": "update"}}
2021-09-05 22:15:40,230 [FTX GW      ] [INFO ]  Received: {"channel": "orderbook", "market": "BTC-PERP", "type": "update", "data": {"time": 1630851341.1771955, "checksum": 1254509723, "bids": [[50478.0, 0.8444], [50458.0, 14.8927], [50450.0, 1.3584]], "asks": [[50492.0, 16.0617], [50507.0, 6.3298]], "action": "update"}}
2021-09-05 22:15:40,252 [FTX GW      ] [INFO ]  Received: {"channel": "orderbook", "market": "BTC-PERP", "type": "update", "data": {"time": 1630851341.206973, "checksum": 3371397462, "bids": [[50491.0, 0.381], [50462.0, 0.9902], [50458.0, 6.9852], [50374.0, 0.0]], "asks": [[50492.0, 16.0347], [50502.0, 0.3977], [50520.0, 1.3349]], "action": "update"}}
2021-09-05 22:15:40,290 [FTX GW      ] [INFO ]  Received: {"channel": "orderbook", "market": "BTC-PERP", "type": "update", "data": {"time": 1630851341.241683, "checksum": 1390764775, "bids": [[50489.0, 0.0362], [50485.0, 0.042], [50481.0, 0.5948], [50470.0, 7.1349], [50463.0, 12.0317], [50375.0, 0.0]], "asks": [[50492.0, 7.4977], [50499.0, 0.2077], [50532.0, 0.0301], [50572.0, 0.5322], [50593.0, 0.091]], "action": "update"}}
2021-09-05 22:15:40,314 [FTX GW      ] [INFO ]  Received: {"channel": "orderbook", "market": "BTC-PERP", "type": "update", "data": {"time": 1630851341.2651713, "checksum": 333671356, "bids": [[50491.0, 0.1873], [50463.0, 11.9903], [50458.0, 6.4743], [50442.0, 0.1824], [50376.0, 0.0]], "asks": [[50593.0, 0.121]], "action": "update"}}
2021-09-05 22:15:40,357 [FTX GW      ] [INFO ]  Received: {"channel": "orderbook", "market": "BTC-PERP", "type": "update", "data": {"time": 1630851341.3146439, "checksum": 1770013238, "bids": [[50489.0, 0.6306], [50478.0, 0.5944]], "asks": [[50498.0, 0.1867], [50519.0, 0.1663], [50531.0, 0.1913]], "action": "update"}}
2021-09-05 22:15:40,381 [FTX GW      ] [INFO ]  Received: {"channel": "orderbook", "market": "BTC-PERP", "type": "update", "data": {"time": 1630851341.335643, "checksum": 2860480486, "bids": [[50472.0, 3.1155], [50471.0, 0.78]], "asks": [[50492.0, 7.5769], [50495.0, 1.2101], [50499.0, 0.3444], [50501.0, 0.4354], [50533.0, 5.0906], [50542.0, 4.7936], [50593.0, 0.151]], "action": "update"}}
2021-09-05 22:15:40,404 [FTX GW      ] [INFO ]  Received: {"channel": "orderbook", "market": "BTC-PERP", "type": "update", "data": {"time": 1630851341.3627334, "checksum": 4055777929, "bids": [[50468.0, 5.5098], [50464.0, 0.9056], [50411.0, 0.7967]], "asks": [], "action": "update"}}
2021-09-05 22:15:40,434 [FTX GW      ] [INFO ]  Received: {"channel": "orderbook", "market": "BTC-PERP", "type": "update", "data": {"time": 1630851341.3885744, "checksum": 3506028738, "bids": [[50489.0, 0.0362], [50472.0, 3.1556]], "asks": [[50492.0, 7.5777], [50515.0, 7.497]], "action": "update"}}
2021-09-05 22:15:40,455 [FTX GW      ] [INFO ]  Received: {"channel": "orderbook", "market": "BTC-PERP", "type": "update", "data": {"time": 1630851341.4133623, "checksum": 1894708495, "bids": [[50491.0, 1.0717], [50476.0, 3.3234], [50412.0, 0.269], [50402.0, 0.0693]], "asks": [], "action": "update"}}
2021-09-05 22:15:40,483 [FTX GW      ] [INFO ]  Received: {"channel": "orderbook", "market": "BTC-PERP", "type": "update", "data": {"time": 1630851341.4379828, "checksum": 774306263, "bids": [[50490.0, 0.0], [50464.0, 0.8642], [50411.0, 0.2262], [50386.0, 9.9953], [50376.0, 0.1911]], "asks": [[50493.0, 0.7951], [50539.0, 0.8058], [50597.0, 0.6]], "action": "update"}}
2021-09-05 22:15:40,507 [FTX GW      ] [INFO ]  Received: {"channel": "orderbook", "market": "BTC-PERP", "type": "update", "data": {"time": 1630851341.464062, "checksum": 3836738393, "bids": [[50491.0, 1.5417], [50472.0, 3.1953], [50396.0, 0.2413], [50392.0, 0.5177]], "asks": [[50499.0, 0.3714]], "action": "update"}}
2021-09-05 22:15:40,532 [FTX GW      ] [INFO ]  Received: {"channel": "orderbook", "market": "BTC-PERP", "type": "update", "data": {"time": 1630851341.4881253, "checksum": 2754573258, "bids": [[50491.0, 2.5417], [50490.0, 0.6684], [50469.0, 5.4609], [50449.0, 1.223], [50376.0, 0.0]], "asks": [[50492.0, 7.6569], [50521.0, 0.1166], [50544.0, 0.9385]], "action": "update"}}
2021-09-05 22:15:40,558 [FTX GW      ] [INFO ]  Received: {"channel": "orderbook", "market": "BTC-PERP", "type": "update", "data": {"time": 1630851341.5112548, "checksum": 1178924126, "bids": [[50491.0, 1.5417], [50477.0, 0.5671], [50459.0, 5.3035], [50405.0, 3.0337], [50378.0, 0.0]], "asks": [], "action": "update"}}
2021-09-05 22:15:40,576 [FTX GW      ] [INFO ]  Received: {"channel": "orderbook", "market": "BTC-PERP", "type": "update", "data": {"time": 1630851341.5367684, "checksum": 1525956288, "bids": [[50464.0, 0.9056], [50460.0, 1.2241]], "asks": [], "action": "update"}}
2021-09-05 22:15:40,594 [FTX GW      ] [INFO ]  Sending ping to WebSocket server
2021-09-05 22:15:40,609 [FTX GW      ] [INFO ]  Received: {"channel": "orderbook", "market": "BTC-PERP", "type": "update", "data": {"time": 1630851341.5629513, "checksum": 820764114, "bids": [[50491.0, 1.624], [50463.0, 11.8235], [50462.0, 0.0], [50449.0, 0.712], [50378.0, 0.6025]], "asks": [[50492.0, 7.5777], [50511.0, 0.0936], [50541.0, 4.0341]], "action": "update"}}
2021-09-05 22:15:40,632 [FTX GW      ] [INFO ]  Received: {"channel": "orderbook", "market": "BTC-PERP", "type": "update", "data": {"time": 1630851341.587709, "checksum": 1842347571, "bids": [[50440.0, 1.08], [50415.0, 0.5705], [50399.0, 0.1726], [50378.0, 0.0]], "asks": [[50492.0, 7.2977], [50545.0, 0.1801]], "action": "update"}}
2021-09-05 22:15:40,659 [FTX GW      ] [INFO ]  Received: {"channel": "orderbook", "market": "BTC-PERP", "type": "update", "data": {"time": 1630851341.6181664, "checksum": 1337219350, "bids": [[50491.0, 6.4289], [50464.0, 0.8642], [50394.0, 1.5693]], "asks": [[50492.0, 6.8966], [50505.0, 0.4371], [50542.0, 4.8036]], "action": "update"}}
2021-09-05 22:15:40,676 [FTX GW      ] [INFO ]  Received: {"type": "pong"}
2021-09-05 22:15:40,692 [FTX GW      ] [INFO ]  Received: {"channel": "orderbook", "market": "BTC-PERP", "type": "update", "data": {"time": 1630851341.6494281, "checksum": 3257939609, "bids": [[50491.0, 6.6016], [50490.0, 0.0], [50478.0, 0.0], [50468.0, 4.9154], [50466.0, 0.9902], [50378.0, 0.6025]], "asks": [[50494.0, 0.5401], [50516.0, 0.1571], [50526.0, 1.3874], [50573.0, 2.7653], [50597.0, 0.0]], "action": "update"}}
2021-09-05 22:15:40,716 [FTX GW      ] [INFO ]  Received: {"channel": "orderbook", "market": "BTC-PERP", "type": "update", "data": {"time": 1630851341.665072, "checksum": 771928686, "bids": [[50457.0, 1.8121]], "asks": [[50492.0, 6.9758], [50508.0, 1.8357], [50518.0, 0.7875]], "action": "update"}}
2021-09-05 22:15:40,763 [FTX GW      ] [INFO ]  Received: {"channel": "orderbook", "market": "BTC-PERP", "type": "update", "data": {"time": 1630851341.6930368, "checksum": 3151026416, "bids": [[50466.0, 1.2983], [50464.0, 1.031], [50460.0, 0.8366], [50452.0, 0.1692]], "asks": [[50492.0, 5.9658], [50507.0, 6.4289], [50513.0, 1.963]], "action": "update"}}
2021-09-05 22:15:40,764 [FTX GW      ] [INFO ]  Received: {"channel": "orderbook", "market": "BTC-PERP", "type": "update", "data": {"time": 1630851341.715294, "checksum": 1699077784, "bids": [[50481.0, 0.4957], [50441.0, 1.4935]], "asks": [[50492.0, 3.5943]], "action": "update"}}
2021-09-05 22:15:40,781 [FTX GW      ] [INFO ]  Received: {"channel": "orderbook", "market": "BTC-PERP", "type": "update", "data": {"time": 1630851341.7417417, "checksum": 1007449649, "bids": [[50491.0, 7.2081], [50490.0, 0.432], [50481.0, 0.3966], [50458.0, 5.0914], [50385.0, 7.111], [50378.0, 0.0]], "asks": [[50492.0, 1.9878], [50493.0, 0.3503], [50494.0, 0.139], [50508.0, 1.2413], [50517.0, 8.9239], [50518.0, 0.1931], [50524.0, 3.5238]], "action": "update"}}
2021-09-05 22:15:40,824 [FTX GW      ] [INFO ]  Received: {"channel": "orderbook", "market": "BTC-PERP", "type": "update", "data": {"time": 1630851341.7650642, "checksum": 2318029572, "bids": [[50490.0, 0.7387], [50479.0, 0.0], [50468.0, 4.9568], [50378.0, 0.6025]], "asks": [[50493.0, 0.3465], [50505.0, 0.338], [50507.0, 6.3298], [50515.0, 0.9822], [50517.0, 1.1]], "action": "update"}}
2021-09-05 22:15:40,834 [FTX GW      ] [INFO ]  Received: {"channel": "orderbook", "market": "BTC-PERP", "type": "update", "data": {"time": 1630851341.793237, "checksum": 7064271, "bids": [[50486.0, 0.0991], [50485.0, 0.0], [50465.0, 1.7093], [50458.0, 5.6023]], "asks": [[50509.0, 1.7592], [50515.0, 0.9722], [50519.0, 0.7607], [50535.0, 0.0111]], "action": "update"}}
2021-09-05 22:15:40,856 [FTX GW      ] [INFO ]  Received: {"channel": "orderbook", "market": "BTC-PERP", "type": "update", "data": {"time": 1630851341.816003, "checksum": 3165986177, "bids": [[50491.0, 7.2247], [50489.0, 0.2345], [50468.0, 4.9154]], "asks": [[50492.0, 2.067], [50500.0, 79.0871]], "action": "update"}}
2021-09-05 22:15:40,885 [FTX GW      ] [INFO ]  Received: {"channel": "orderbook", "market": "BTC-PERP", "type": "update", "data": {"time": 1630851341.8409224, "checksum": 1275279978, "bids": [[50490.0, 0.432], [50486.0, 0.1982]], "asks": [[50510.0, 1.6736], [50511.0, 0.1927]], "action": "update"}}
2021-09-05 22:15:40,907 [FTX GW      ] [INFO ]  Received: {"channel": "orderbook", "market": "BTC-PERP", "type": "update", "data": {"time": 1630851341.865383, "checksum": 620431942, "bids": [[50491.0, 7.4647], [50485.0, 0.3962], [50465.0, 1.6993], [50378.0, 0.0]], "asks": [[50492.0, 2.0681]], "action": "update"}}
2021-09-05 22:15:40,930 [FTX GW      ] [INFO ]  Received: {"channel": "orderbook", "market": "BTC-PERP", "type": "update", "data": {"time": 1630851341.8900828, "checksum": 3458133782, "bids": [[50491.0, 7.8247], [50466.0, 0.9902], [50380.0, 51.9276]], "asks": [[50492.0, 3.0681], [50494.0, 0.5401], [50509.0, 1.1648], [50545.0, 0.1903]], "action": "update"}}
2021-09-05 22:15:40,958 [FTX GW      ] [INFO ]  Received: {"channel": "orderbook", "market": "BTC-PERP", "type": "update", "data": {"time": 1630851341.9162345, "checksum": 415919473, "bids": [[50489.0, 0.2045], [50471.0, 1.0868], [50469.0, 5.5023], [50463.0, 11.834]], "asks": [[50492.0, 2.9889], [50512.0, 15.4082], [50520.0, 1.3449], [50540.0, 0.0299]], "action": "update"}}
2021-09-05 22:15:40,982 [FTX GW      ] [INFO ]  Received: {"channel": "orderbook", "market": "BTC-PERP", "type": "update", "data": {"time": 1630851341.9397833, "checksum": 3380561209, "bids": [[50470.0, 7.1449]], "asks": [], "action": "update"}}
2021-09-05 22:15:41,003 [FTX GW      ] [INFO ]  Received: {"channel": "orderbook", "market": "BTC-PERP", "type": "update", "data": {"time": 1630851341.9646726, "checksum": 2153498676, "bids": [[50469.0, 5.4609]], "asks": [[50512.0, 14.8138], [50519.0, 0.1663]], "action": "update"}}
2021-09-05 22:15:41,027 [FTX GW      ] [INFO ]  Received: {"channel": "orderbook", "market": "BTC-PERP", "type": "update", "data": {"time": 1630851341.9894817, "checksum": 3543538181, "bids": [[50466.0, 1.9902], [50381.0, 2.5]], "asks": [], "action": "update"}}
2021-09-05 22:15:41,060 [FTX GW      ] [INFO ]  Received: {"channel": "orderbook", "market": "BTC-PERP", "type": "update", "data": {"time": 1630851342.0145392, "checksum": 4262135553, "bids": [[50470.0, 7.1549]], "asks": [[50492.0, 3.0009], [50511.0, 0.7871]], "action": "update"}}
2021-09-05 22:15:41,083 [FTX GW      ] [INFO ]  Received: {"channel": "orderbook", "market": "BTC-PERP", "type": "update", "data": {"time": 1630851342.0400662, "checksum": 166549634, "bids": [[50491.0, 5.4827], [50484.0, 0.041], [50379.0, 0.0]], "asks": [[50492.0, 3.2609], [50521.0, 0.711]], "action": "update"}}
2021-09-05 22:15:41,123 [FTX GW      ] [INFO ]  Received: {"channel": "orderbook", "market": "BTC-PERP", "type": "update", "data": {"time": 1630851342.0743408, "checksum": 471671513, "bids": [[50469.0, 5.5023], [50437.0, 0.4259], [50426.0, 2.7381]], "asks": [[50492.0, 3.3401], [50536.0, 2.3706], [50541.0, 0.8509]], "action": "update"}}
2021-09-05 22:15:41,177 [FTX GW      ] [INFO ]  Received: {"channel": "orderbook", "market": "BTC-PERP", "type": "update", "data": {"time": 1630851342.0958266, "checksum": 1984391609, "bids": [], "asks": [[50583.0, 0.0184]], "action": "update"}}
2021-09-05 22:15:41,177 [FTX GW      ] [INFO ]  Received: {"channel": "orderbook", "market": "BTC-PERP", "type": "update", "data": {"time": 1630851342.1171625, "checksum": 2721721014, "bids": [[50485.0, 0.0], [50471.0, 0.78], [50466.0, 0.9902], [50380.0, 1.2192], [50379.0, 0.016]], "asks": [[50492.0, 3.2609], [50514.0, 3.3339]], "action": "update"}}
2021-09-05 22:15:41,190 [FTX GW      ] [INFO ]  Received: {"channel": "orderbook", "market": "BTC-PERP", "type": "update", "data": {"time": 1630851342.1456304, "checksum": 186829623, "bids": [[50491.0, 4.9316], [50484.0, 0.06], [50477.0, 0.0], [50469.0, 5.4609], [50468.0, 3.0268], [50434.0, 13.8449], [50433.0, 0.8197], [50378.0, 0.6025]], "asks": [[50492.0, 4.7634], [50508.0, 1.8357], [50511.0, 0.1927], [50527.0, 0.2715]], "action": "update"}}
2021-09-05 22:15:41,213 [FTX GW      ] [INFO ]  Received: {"channel": "orderbook", "market": "BTC-PERP", "type": "update", "data": {"time": 1630851342.1679387, "checksum": 1204962052, "bids": [[50467.0, 5.1882]], "asks": [[50492.0, 3.3184], [50502.0, 0.001], [50515.0, 1.0532], [50580.0, 3.202]], "action": "update"}}
2021-09-05 22:15:41,241 [FTX GW      ] [INFO ]  Received: {"channel": "orderbook", "market": "BTC-PERP", "type": "update", "data": {"time": 1630851342.1930964, "checksum": 2657622568, "bids": [[50481.0, 0.0], [50398.0, 1.2984], [50383.0, 18.3004], [50376.0, 0.1911]], "asks": [[50492.0, 3.7884], [50563.0, 0.3185]], "action": "update"}}
2021-09-05 22:15:41,266 [FTX GW      ] [INFO ]  Received: {"channel": "orderbook", "market": "BTC-PERP", "type": "update", "data": {"time": 1630851342.2171667, "checksum": 2512734834, "bids": [[50491.0, 4.9016], [50472.0, 5.0799]], "asks": [[50492.0, 3.8676]], "action": "update"}}
2021-09-05 22:15:41,293 [FTX GW      ] [INFO ]  Received: {"channel": "orderbook", "market": "BTC-PERP", "type": "update", "data": {"time": 1630851342.2460537, "checksum": 2899741491, "bids": [[50482.0, 2.8962], [50478.0, 0.5671], [50442.0, 3.0071], [50429.0, 4.2436], [50376.0, 0.0]], "asks": [[50492.0, 3.4387], [50538.0, 3.3511]], "action": "update"}}
2021-09-05 22:15:41,332 [FTX GW      ] [INFO ]  Received: {"channel": "orderbook", "market": "BTC-PERP", "type": "update", "data": {"time": 1630851342.2685492, "checksum": 2510378098, "bids": [[50491.0, 4.8351], [50471.0, 0.7619]], "asks": [[50492.0, 3.7987], [50508.0, 1.2413], [50521.0, 0.1166], [50571.0, 0.2559]], "action": "update"}}
2021-09-05 22:15:41,340 [FTX GW      ] [INFO ]  Received: {"channel": "orderbook", "market": "BTC-PERP", "type": "update", "data": {"time": 1630851342.2953994, "checksum": 2157023855, "bids": [[50467.0, 5.2296], [50459.0, 9.8489], [50389.0, 53.6986], [50387.0, 0.5294]], "asks": [[50518.0, 0.7875], [50580.0, 0.8236], [50595.0, 50.7131]], "action": "update"}}
2021-09-05 22:15:41,388 [FTX GW      ] [INFO ]  Received: {"channel": "orderbook", "market": "BTC-PERP", "type": "update", "data": {"time": 1630851342.3288782, "checksum": 2610200321, "bids": [[50472.0, 3.1953], [50465.0, 2.0867], [50462.0, 0.3829], [50378.0, 0.0]], "asks": [[50492.0, 3.6684]], "action": "update"}}
2021-09-05 22:15:41,431 [FTX GW      ] [INFO ]  Received: {"channel": "orderbook", "market": "BTC-PERP", "type": "update", "data": {"time": 1630851342.3778021, "checksum": 794122046, "bids": [[50485.0, 0.03], [50482.0, 2.5], [50467.0, 6.1882], [50379.0, 0.0]], "asks": [[50492.0, 2.3084], [50498.0, 0.1367], [50507.0, 6.9242], [50549.0, 4.431], [50557.0, 1.789], [50564.0, 7.0265], [50585.0, 1.6968]], "action": "update"}}
2021-09-05 22:15:41,442 [FTX GW      ] [INFO ]  Received: {"channel": "orderbook", "market": "BTC-PERP", "type": "update", "data": {"time": 1630851342.40351, "checksum": 2215663532, "bids": [[50465.0, 2.0667], [50459.0, 9.5046], [50393.0, 0.0], [50392.0, 1.217], [50379.0, 0.016]], "asks": [], "action": "update"}}
2021-09-05 22:15:41,467 [FTX GW      ] [INFO ]  Received: {"channel": "orderbook", "market": "BTC-PERP", "type": "update", "data": {"time": 1630851342.4231114, "checksum": 1928719672, "bids": [[50469.0, 7.3716], [50467.0, 5.1882], [50435.0, 1.3436]], "asks": [[50492.0, 2.3876], [50499.0, 0.4214], [50544.0, 2.1277]], "action": "update"}}
2021-09-05 22:15:41,493 [FTX GW      ] [INFO ]  Received: {"channel": "orderbook", "market": "BTC-PERP", "type": "update", "data": {"time": 1630851342.447886, "checksum": 991089261, "bids": [[50484.0, 0.041], [50467.0, 4.8818], [50457.0, 1.504], [50398.0, 1.0427]], "asks": [[50517.0, 0.8443], [50529.0, 3.6205], [50538.0, 3.1035], [50592.0, 12.072]], "action": "update"}}
2021-09-05 22:15:41,512 [FTX GW      ] [INFO ]  Received: {"channel": "orderbook", "market": "BTC-PERP", "type": "update", "data": {"time": 1630851342.471298, "checksum": 2397172647, "bids": [[50475.0, 3.3904], [50465.0, 2.6592], [50434.0, 17.3542]], "asks": [], "action": "update"}}
2021-09-05 22:15:41,549 [FTX GW      ] [INFO ]  Received: {"channel": "orderbook", "market": "BTC-PERP", "type": "update", "data": {"time": 1630851342.4966686, "checksum": 3023640868, "bids": [[50491.0, 4.2951], [50485.0, 0.0], [50481.0, 0.3962], [50470.0, 7.1749], [50467.0, 4.9232], [50447.0, 10.2424], [50399.0, 7.1912]], "asks": [[50492.0, 2.5984], [50500.0, 78.8888]], "action": "update"}}
2021-09-05 22:15:41,561 [FTX GW      ] [INFO ]  Received: {"channel": "orderbook", "market": "BTC-PERP", "type": "update", "data": {"time": 1630851342.5213263, "checksum": 431271979, "bids": [[50491.0, 3.7751], [50470.0, 7.1649], [50467.0, 4.8818], [50390.0, 4.5264]], "asks": [[50492.0, 4.0884], [50511.0, 0.0936]], "action": "update"}}
2021-09-05 22:15:41,600 [FTX GW      ] [INFO ]  Received: {"channel": "orderbook", "market": "BTC-PERP", "type": "update", "data": {"time": 1630851342.5473368, "checksum": 148770932, "bids": [[50491.0, 3.4151], [50489.0, 0.0062], [50440.0, 1.1]], "asks": [[50492.0, 6.2784], [50549.0, 1.6119], [50585.0, 4.0752]], "action": "update"}}
2021-09-05 22:15:41,611 [FTX GW      ] [INFO ]  Received: {"channel": "orderbook", "market": "BTC-PERP", "type": "update", "data": {"time": 1630851342.5721946, "checksum": 2124096196, "bids": [[50469.0, 5.4609], [50436.0, 25.5443]], "asks": [[50548.0, 26.3047], [50593.0, 0.181]], "action": "update"}}
2021-09-05 22:15:41,642 [FTX GW      ] [INFO ]  Received: {"channel": "orderbook", "market": "BTC-PERP", "type": "update", "data": {"time": 1630851342.5966856, "checksum": 2065425733, "bids": [[50459.0, 5.3622]], "asks": [[50493.0, 0.7476], [50498.0, 0.335], [50507.0, 7.0233], [50553.0, 3.2505]], "action": "update"}}
2021-09-05 22:15:41,660 [FTX GW      ] [INFO ]  Received: {"channel": "orderbook", "market": "BTC-PERP", "type": "update", "data": {"time": 1630851342.6217382, "checksum": 3021951904, "bids": [[50467.0, 4.9232], [50457.0, 6.0492]], "asks": [[50518.0, 0.8806]], "action": "update"}}
2021-09-05 22:15:41,712 [FTX GW      ] [INFO ]  Received: {"channel": "orderbook", "market": "BTC-PERP", "type": "update", "data": {"time": 1630851342.664716, "checksum": 1678084819, "bids": [[50479.0, 0.03], [50471.0, 2.6774], [50467.0, 4.9332], [50463.0, 12.834], [50457.0, 1.504], [50379.0, 0.0]], "asks": [[50492.0, 6.7587], [50548.0, 26.5523], [50553.0, 6.0695]], "action": "update"}}
2021-09-05 22:15:41,726 [FTX GW      ] [INFO ]  Received: {"channel": "orderbook", "market": "BTC-PERP", "type": "update", "data": {"time": 1630851342.6843781, "checksum": 1271159243, "bids": [[50491.0, 6.4811], [50479.0, 0.0], [50467.0, 4.8918], [50379.0, 0.016]], "asks": [[50497.0, 0.0844]], "action": "update"}}
2021-09-05 22:15:41,746 [FTX GW      ] [INFO ]  Received: {"channel": "orderbook", "market": "BTC-PERP", "type": "update", "data": {"time": 1630851342.708475, "checksum": 1357712460, "bids": [[50458.0, 5.0914], [50407.0, 0.5431]], "asks": [[50492.0, 6.6795], [50530.0, 0.1527]], "action": "update"}}
2021-09-05 22:15:41,774 [FTX GW      ] [INFO ]  Received: {"channel": "orderbook", "market": "BTC-PERP", "type": "update", "data": {"time": 1630851342.733256, "checksum": 433921948, "bids": [[50491.0, 7.3011], [50407.0, 0.7988], [50383.0, 0.2202]], "asks": [[50492.0, 6.2784], [50526.0, 1.6431]], "action": "update"}}
2021-09-05 22:15:41,800 [FTX GW      ] [INFO ]  Received: {"channel": "orderbook", "market": "BTC-PERP", "type": "update", "data": {"time": 1630851342.7583134, "checksum": 2639598763, "bids": [[50466.0, 0.0], [50378.0, 0.6025]], "asks": [[50492.0, 5.6684]], "action": "update"}}
2021-09-05 22:15:41,839 [FTX GW      ] [INFO ]  Received: {"channel": "orderbook", "market": "BTC-PERP", "type": "update", "data": {"time": 1630851342.7858312, "checksum": 4237491968, "bids": [[50487.0, 0.03], [50378.0, 0.0]], "asks": [[50492.0, 4.9976], [50495.0, 1.1669], [50507.0, 6.9242]], "action": "update"}}
2021-09-05 22:15:41,851 [FTX GW      ] [INFO ]  Received: {"channel": "orderbook", "market": "BTC-PERP", "type": "update", "data": {"time": 1630851342.811337, "checksum": 3086809831, "bids": [[50465.0, 2.7006]], "asks": [[50492.0, 3.3301], [50493.0, 0.3465], [50494.0, 0.0956]], "action": "update"}}
2021-09-05 22:15:41,883 [FTX GW      ] [INFO ]  Received: {"channel": "orderbook", "market": "BTC-PERP", "type": "update", "data": {"time": 1630851342.8391795, "checksum": 358985210, "bids": [[50491.0, 7.2724], [50481.0, 0.0], [50378.0, 0.6025]], "asks": [[50492.0, 3.2509], [50509.0, 7.0102], [50524.0, 1.6228]], "action": "update"}}
2021-09-05 22:15:41,944 [FTX GW      ] [INFO ]  Received: {"channel": "orderbook", "market": "BTC-PERP", "type": "update", "data": {"time": 1630851342.887809, "checksum": 2797743555, "bids": [[50491.0, 7.8724], [50468.0, 4.017], [50465.0, 2.6592]], "asks": [[50494.0, 0.4967], [50506.0, 10.0097], [50509.0, 1.1648], [50512.0, 14.9129], [50543.0, 0.0353], [50552.0, 0.1144]], "action": "update"}}
2021-09-05 22:15:41,973 [FTX GW      ] [INFO ]  Received: {"channel": "orderbook", "market": "BTC-PERP", "type": "update", "data": {"time": 1630851342.9343352, "checksum": 1884265094, "bids": [[50485.0, 0.3962], [50481.0, 0.6466], [50478.0, 0.0], [50473.0, 10.6103], [50471.0, 2.4274], [50457.0, 2.015], [50378.0, 0.0]], "asks": [[50492.0, 3.3301], [50516.0, 6.5616], [50525.0, 5.0618], [50530.0, 0.1113]], "action": "update"}}
2021-09-05 22:15:41,994 [FTX GW      ] [INFO ]  Received: {"channel": "orderbook", "market": "BTC-PERP", "type": "update", "data": {"time": 1630851342.9581544, "checksum": 2888413308, "bids": [[50478.0, 0.25], [50379.0, 0.0]], "asks": [], "action": "update"}}
2021-09-05 22:15:42,020 [FTX GW      ] [INFO ]  Received: {"channel": "orderbook", "market": "BTC-PERP", "type": "update", "data": {"time": 1630851342.982569, "checksum": 1280025036, "bids": [], "asks": [[50544.0, 2.3137]], "action": "update"}}
2021-09-05 22:15:42,050 [FTX GW      ] [INFO ]  Received: {"channel": "orderbook", "market": "BTC-PERP", "type": "update", "data": {"time": 1630851343.0109887, "checksum": 3438777205, "bids": [[50480.0, 0.1], [50479.0, 0.5671], [50467.0, 4.9332], [50381.0, 0.0], [50380.0, 0.0]], "asks": [[50492.0, 3.2509], [50548.0, 26.8493]], "action": "update"}}
2021-09-05 22:15:42,073 [FTX GW      ] [INFO ]  Received: {"channel": "orderbook", "market": "BTC-PERP", "type": "update", "data": {"time": 1630851343.0352228, "checksum": 3716697528, "bids": [[50491.0, 7.8677], [50485.0, 0.0], [50381.0, 2.5]], "asks": [], "action": "update"}}
2021-09-05 22:15:42,097 [FTX GW      ] [INFO ]  Received: {"channel": "orderbook", "market": "BTC-PERP", "type": "update", "data": {"time": 1630851343.0590255, "checksum": 3432682, "bids": [[50491.0, 6.3327], [50467.0, 4.8918], [50384.0, 18.1437]], "asks": [[50492.0, 3.2498]], "action": "update"}}
2021-09-05 22:15:42,126 [FTX GW      ] [INFO ]  Received: {"channel": "orderbook", "market": "BTC-PERP", "type": "update", "data": {"time": 1630851343.0844264, "checksum": 2295377033, "bids": [], "asks": [[50492.0, 2.9898], [50493.0, 0.7476]], "action": "update"}}
2021-09-05 22:15:42,152 [FTX GW      ] [INFO ]  Received: {"channel": "orderbook", "market": "BTC-PERP", "type": "update", "data": {"time": 1630851343.111023, "checksum": 2086867451, "bids": [[50475.0, 2.7979], [50474.0, 1.8855], [50472.0, 2.9453], [50465.0, 2.0667]], "asks": [[50492.0, 3.0661], [50548.0, 26.8778]], "action": "update"}}
2021-09-05 22:15:42,174 [FTX GW      ] [INFO ]  Received: {"channel": "orderbook", "market": "BTC-PERP", "type": "update", "data": {"time": 1630851343.1335807, "checksum": 216556862, "bids": [[50482.0, 2.8962], [50480.0, 0.35], [50479.0, 0.8171]], "asks": [[50492.0, 3.1453], [50513.0, 9.3716], [50581.0, 2.8479]], "action": "update"}}
2021-09-05 22:15:42,194 [FTX GW      ] [INFO ]  Received: {"channel": "orderbook", "market": "BTC-PERP", "type": "update", "data": {"time": 1630851343.1573944, "checksum": 2583850754, "bids": [[50471.0, 2.7009], [50440.0, 1.08], [50427.0, 0.2235]], "asks": [[50492.0, 2.1453], [50516.0, 0.1571], [50530.0, 0.1527]], "action": "update"}}
2021-09-05 22:15:42,220 [FTX GW      ] [INFO ]  Received: {"channel": "orderbook", "market": "BTC-PERP", "type": "update", "data": {"time": 1630851343.1823864, "checksum": 455580493, "bids": [[50491.0, 8.4887], [50482.0, 2.5], [50467.0, 4.9288], [50461.0, 0.9624]], "asks": [], "action": "update"}}
2021-09-05 22:15:42,254 [FTX GW      ] [INFO ]  Received: {"channel": "orderbook", "market": "BTC-PERP", "type": "update", "data": {"time": 1630851343.2109742, "checksum": 141816972, "bids": [], "asks": [[50492.0, 2.0661], [50533.0, 3.708]], "action": "update"}}
2021-09-05 22:15:42,290 [FTX GW      ] [INFO ]  Received: {"channel": "orderbook", "market": "BTC-PERP", "type": "update", "data": {"time": 1630851343.2327335, "checksum": 2364066119, "bids": [[50491.0, 6.3327], [50467.0, 4.8818]], "asks": [], "action": "update"}}
2021-09-05 22:15:42,302 [FTX GW      ] [INFO ]  Received: {"channel": "orderbook", "market": "BTC-PERP", "type": "update", "data": {"time": 1630851343.2594168, "checksum": 1357830855, "bids": [[50491.0, 4.8017]], "asks": [], "action": "update"}}
2021-09-05 22:15:42,319 [FTX GW      ] [INFO ]  Received: {"channel": "orderbook", "market": "BTC-PERP", "type": "update", "data": {"time": 1630851343.2830276, "checksum": 4130683018, "bids": [[50484.0, 0.4372], [50457.0, 1.504], [50387.0, 0.7154], [50386.0, 10.2923]], "asks": [[50492.0, 3.0661]], "action": "update"}}
2021-09-05 22:15:42,349 [FTX GW      ] [INFO ]  Received: {"channel": "orderbook", "market": "BTC-PERP", "type": "update", "data": {"time": 1630851343.3095553, "checksum": 2308371177, "bids": [[50491.0, 3.6917], [50381.0, 2.498]], "asks": [[50492.0, 3.7961], [50572.0, 0.4908]], "action": "update"}}
2021-09-05 22:15:42,374 [FTX GW      ] [INFO ]  Received: {"channel": "orderbook", "market": "BTC-PERP", "type": "update", "data": {"time": 1630851343.3335054, "checksum": 1256581000, "bids": [[50491.0, 3.6751], [50484.0, 0.041], [50470.0, 4.2945]], "asks": [[50492.0, 4.5761], [50541.0, 2.2335]], "action": "update"}}
2021-09-05 22:15:42,406 [FTX GW      ] [INFO ]  Received: {"channel": "orderbook", "market": "BTC-PERP", "type": "update", "data": {"time": 1630851343.3618581, "checksum": 2917956891, "bids": [[50491.0, 3.0022], [50486.0, 0.3965], [50466.0, 0.037], [50381.0, 0.0]], "asks": [[50492.0, 6.3753]], "action": "update"}}
2021-09-05 22:15:42,439 [FTX GW      ] [INFO ]  Received: {"channel": "orderbook", "market": "BTC-PERP", "type": "update", "data": {"time": 1630851343.3848426, "checksum": 760845768, "bids": [[50491.0, 3.0426], [50470.0, 4.3045], [50466.0, 0.0], [50412.0, 0.219], [50381.0, 2.498]], "asks": [[50565.0, 0.013]], "action": "update"}}
2021-09-05 22:15:42,452 [FTX GW      ] [INFO ]  Received: {"channel": "orderbook", "market": "BTC-PERP", "type": "update", "data": {"time": 1630851343.4126792, "checksum": 2442463168, "bids": [[50491.0, 3.0436], [50420.0, 1.5908], [50391.0, 0.0], [50380.0, 1.2192]], "asks": [[50492.0, 6.2961], [50508.0, 8.9815]], "action": "update"}}
2021-09-05 22:15:42,476 [FTX GW      ] [INFO ]  Received: {"channel": "orderbook", "market": "BTC-PERP", "type": "update", "data": {"time": 1630851343.4364672, "checksum": 1967386981, "bids": [[50481.0, 1.0428], [50413.0, 0.0612]], "asks": [[50492.0, 6.6561], [50541.0, 1.663]], "action": "update"}}
2021-09-05 22:15:42,514 [FTX GW      ] [INFO ]  Received: {"channel": "orderbook", "market": "BTC-PERP", "type": "update", "data": {"time": 1630851343.4637325, "checksum": 1756044602, "bids": [[50491.0, 2.8936], [50487.0, 0.0], [50469.0, 2.7906], [50465.0, 2.0767], [50415.0, 0.0], [50379.0, 0.016], [50378.0, 0.6045]], "asks": [[50492.0, 6.6972], [50513.0, 1.963]], "action": "update"}}
2021-09-05 22:15:42,542 [FTX GW      ] [INFO ]  Received: {"channel": "orderbook", "market": "BTC-PERP", "type": "update", "data": {"time": 1630851343.5039325, "checksum": 2887636734, "bids": [[50491.0, 3.1736], [50466.0, 0.037], [50378.0, 0.0]], "asks": [[50508.0, 1.2413], [50513.0, 1.964]], "action": "update"}}
2021-09-05 22:15:42,592 [FTX GW      ] [INFO ]  Sending ping to WebSocket server
2021-09-05 22:15:42,592 [FTX GW      ] [INFO ]  Received: {"channel": "orderbook", "market": "BTC-PERP", "type": "update", "data": {"time": 1630851343.5313497, "checksum": 219244709, "bids": [[50468.0, 3.0268], [50463.0, 13.345]], "asks": [[50492.0, 6.7764], [50512.0, 14.8138]], "action": "update"}}
2021-09-05 22:15:42,597 [FTX GW      ] [INFO ]  Received: {"channel": "orderbook", "market": "BTC-PERP", "type": "update", "data": {"time": 1630851343.5535357, "checksum": 1052566149, "bids": [[50491.0, 2.8136], [50472.0, 2.9052], [50466.0, 0.0], [50378.0, 0.6045]], "asks": [[50507.0, 6.3298], [50518.0, 0.2862], [50592.0, 12.1134]], "action": "update"}}
2021-09-05 22:15:42,618 [FTX GW      ] [INFO ]  Received: {"channel": "orderbook", "market": "BTC-PERP", "type": "update", "data": {"time": 1630851343.578882, "checksum": 3269799729, "bids": [[50489.0, 0.0], [50488.0, 13.5444], [50416.0, 0.963], [50376.0, 0.1911]], "asks": [[50499.0, 0.5214], [50525.0, 3.1579], [50542.0, 1.9909], [50544.0, 2.8842], [50579.0, 0.0], [50597.0, 0.6]], "action": "update"}}
2021-09-05 22:15:42,657 [FTX GW      ] [INFO ]  Received: {"channel": "orderbook", "market": "BTC-PERP", "type": "update", "data": {"time": 1630851343.6093261, "checksum": 1655140732, "bids": [[50464.0, 1.8544], [50427.0, 4.0754], [50409.0, 0.1045]], "asks": [[50499.0, 0.4214], [50509.0, 1.2639], [50517.0, 1.4387]], "action": "update"}}
2021-09-05 22:15:42,677 [FTX GW      ] [INFO ]  Received: {"type": "pong"}
2021-09-05 22:15:42,689 [FTX GW      ] [INFO ]  Received: {"channel": "orderbook", "market": "BTC-PERP", "type": "update", "data": {"time": 1630851343.6281762, "checksum": 3436205380, "bids": [[50491.0, 3.2536], [50488.0, 13.5144], [50463.0, 12.834], [50461.0, 0.9434]], "asks": [[50492.0, 6.6561]], "action": "update"}}
2021-09-05 22:15:42,698 [FTX GW      ] [INFO ]  Received: {"channel": "orderbook", "market": "BTC-PERP", "type": "update", "data": {"time": 1630851343.6586986, "checksum": 1553310842, "bids": [[50491.0, 5.1976]], "asks": [[50492.0, 6.2961]], "action": "update"}}
2021-09-05 22:15:42,747 [FTX GW      ] [INFO ]  Received: {"channel": "orderbook", "market": "BTC-PERP", "type": "update", "data": {"time": 1630851343.6832435, "checksum": 949461735, "bids": [[50491.0, 5.7376], [50481.0, 0.6466], [50465.0, 2.0667], [50440.0, 1.1]], "asks": [[50524.0, 3.5364], [50593.0, 0.1821]], "action": "update"}}
2021-09-05 22:15:42,760 [FTX GW      ] [INFO ]  Received: {"channel": "orderbook", "market": "BTC-PERP", "type": "update", "data": {"time": 1630851343.7133148, "checksum": 2834111115, "bids": [[50491.0, 6.0976], [50456.0, 6.7055]], "asks": [[50508.0, 1.8357]], "action": "update"}}
2021-09-05 22:15:42,776 [FTX GW      ] [INFO ]  Received: {"channel": "orderbook", "market": "BTC-PERP", "type": "update", "data": {"time": 1630851343.7376127, "checksum": 3347399515, "bids": [[50479.0, 0.25], [50471.0, 2.7199], [50427.0, 4.0454]], "asks": [[50575.0, 0.0997], [50581.0, 18.6046]], "action": "update"}}
2021-09-05 22:15:42,808 [FTX GW      ] [INFO ]  Received: {"channel": "orderbook", "market": "BTC-PERP", "type": "update", "data": {"time": 1630851343.759287, "checksum": 1688955805, "bids": [[50491.0, 4.1536], [50487.0, 0.03], [50483.0, 0.5879], [50376.0, 0.0]], "asks": [[50492.0, 6.3753]], "action": "update"}}
2021-09-05 22:15:42,861 [FTX GW      ] [INFO ]  Received: {"channel": "orderbook", "market": "BTC-PERP", "type": "update", "data": {"time": 1630851343.8089392, "checksum": 2252071972, "bids": [[50470.0, 4.3145], [50457.0, 0.0], [50376.0, 0.1911]], "asks": [[50492.0, 6.2961], [50543.0, 2.848]], "action": "update"}}
2021-09-05 22:15:42,874 [FTX GW      ] [INFO ]  Received: {"channel": "orderbook", "market": "BTC-PERP", "type": "update", "data": {"time": 1630851343.835639, "checksum": 2373362333, "bids": [[50480.0, 0.9171], [50463.0, 13.0009]], "asks": [[50540.0, 0.0324]], "action": "update"}}
2021-09-05 22:15:42,895 [FTX GW      ] [INFO ]  Received: {"channel": "orderbook", "market": "BTC-PERP", "type": "update", "data": {"time": 1630851343.8582866, "checksum": 2768582339, "bids": [[50483.0, 3.5279], [50471.0, 0.8044], [50455.0, 5.2242]], "asks": [], "action": "update"}}
2021-09-05 22:15:42,924 [FTX GW      ] [INFO ]  Received: {"channel": "orderbook", "market": "BTC-PERP", "type": "update", "data": {"time": 1630851343.8832421, "checksum": 956655791, "bids": [[50481.0, 0.25], [50411.0, 3.0529]], "asks": [[50492.0, 6.3046], [50506.0, 9.613], [50524.0, 1.6228]], "action": "update"}}
2021-09-05 22:15:42,974 [FTX GW      ] [INFO ]  Received: {"channel": "orderbook", "market": "BTC-PERP", "type": "update", "data": {"time": 1630851343.932874, "checksum": 4195811002, "bids": [], "asks": [[50492.0, 6.3838]], "action": "update"}}
2021-09-05 22:15:42,998 [FTX GW      ] [INFO ]  Received: {"channel": "orderbook", "market": "BTC-PERP", "type": "update", "data": {"time": 1630851343.9587655, "checksum": 3267944319, "bids": [[50469.0, 4.6972], [50466.0, 0.037], [50376.0, 0.0]], "asks": [[50492.0, 6.3046], [50493.0, 0.7937], [50526.0, 3.56]], "action": "update"}}
